/opt/conda/lib/python3.8/site-packages/torchvision/models/_utils.py:208: UserWarning: The parameter 'pretrained' is deprecated since 0.13 and will be removed in 0.15, please use 'weights' instead.
  warnings.warn(
/opt/conda/lib/python3.8/site-packages/torchvision/models/_utils.py:223: UserWarning: Arguments other than a weight enum or `None` for 'weights' are deprecated since 0.13 and will be removed in 0.15. The current behavior is equivalent to passing `weights=ResNet50_Weights.IMAGENET1K_V1`. You can also use `weights=ResNet50_Weights.DEFAULT` to get the most up-to-date weights.
  warnings.warn(msg)
NOTE! Installing ujson may make loading annotations faster.
DLL 2023-07-12 20:15:36.177470 - PARAMETER dataset path : /data/object_detection  epochs : 1  batch size : 48  eval batch size : 32  no cuda : False  seed : None  checkpoint path : None  mode : benchmark-training  eval on epochs : [21, 31, 37, 42, 48, 53, 59, 64]  lr decay epochs : [43, 54]  learning rate : 0.0  momentum : 0.9  weight decay : 0.0005  lr warmup : None  backbone : resnet50  backbone path : None  num workers : 4  AMP : False  precision : fp32 
Using seed = 4198
loading annotations into memory...
Traceback (most recent call last):
  File "main.py", line 286, in <module>
    train(train_loop_func, logger, args)
  File "main.py", line 146, in train
    cocoGt = get_coco_ground_truth(args)
  File "/workspace/benchmark/Detection/SSD/ssd/data.py", line 73, in get_coco_ground_truth
    cocoGt = COCO(annotation_file=val_annotate, use_ext=True)
  File "/opt/conda/lib/python3.8/site-packages/pycocotools/coco.py", line 89, in __init__
    dataset = json.load(open(annotation_file, 'r'))
FileNotFoundError: [Errno 2] No such file or directory: '/data/object_detection/annotations/instances_val2017.json'
ERROR:torch.distributed.elastic.multiprocessing.api:failed (exitcode: 1) local_rank: 0 (pid: 5329) of binary: /opt/conda/bin/python
Traceback (most recent call last):
  File "/opt/conda/bin/torchrun", line 33, in <module>
    sys.exit(load_entry_point('torch==1.13.0a0+d0d6b1f', 'console_scripts', 'torchrun')())
  File "/opt/conda/lib/python3.8/site-packages/torch/distributed/elastic/multiprocessing/errors/__init__.py", line 345, in wrapper
    return f(*args, **kwargs)
  File "/opt/conda/lib/python3.8/site-packages/torch/distributed/run.py", line 762, in main
    run(args)
  File "/opt/conda/lib/python3.8/site-packages/torch/distributed/run.py", line 753, in run
    elastic_launch(
  File "/opt/conda/lib/python3.8/site-packages/torch/distributed/launcher/api.py", line 132, in __call__
    return launch_agent(self._config, self._entrypoint, list(args))
  File "/opt/conda/lib/python3.8/site-packages/torch/distributed/launcher/api.py", line 246, in launch_agent
    raise ChildFailedError(
torch.distributed.elastic.multiprocessing.errors.ChildFailedError: 
============================================================
main.py FAILED
------------------------------------------------------------
Failures:
  <NO_OTHER_FAILURES>
------------------------------------------------------------
Root Cause (first observed failure):
[0]:
  time      : 2023-07-12_20:15:40
  host      : 24a2da7181c1
  rank      : 0 (local_rank: 0)
  exitcode  : 1 (pid: 5329)
  error_file: <N/A>
  traceback : To enable traceback see: https://pytorch.org/docs/stable/elastic/errors.html
============================================================
DONE!
